tests/real-bug-02/expected-result.csv
A,6037050,20
A,6037025,50
A,6037000,11
A,6036975,32
A,6036950,43
A,6036925,28
A,6036900,13
A,6036875,45
A,6036850,21
A,6036825,7
A,6036750,16
A,6036725,13
A,6036700,44
B,6036175,22
B,6036150,46
B,6036125,50
B,6036100,29
B,6036075,19
B,6036050,20
B,6036025,43
B,6036000,5
B,6035975,42
B,6035950,30
